File: Sb_NativeOxide_SampleFit_PRO.vms
VAMAS Surface Chemical Analysis Standard Data Transfer Format 1988 May 4
Not Specified
Not Specified
Not Specified
FILE:09092210.pro;BATCH:;DESC:JRG_KN_SbatCu_addstudies_DW_cPANpol;
60
Casa Info Follows CasaXPS Version 2.3.25PR1.0
0
SOFH
Platform: PC
Technique: XPS
FileType:  DEPTHPRO
FileDesc: JRG_KN_SbatCu_addstudies_DW_cPANpol
FileDate: 122 9 9
AcqFileDate: 122 9 9
AcqFilename: 09092210.pro
ScanMode: scan
StagePosition: 0.0 0.0 0.0 45.0 0.0
XraySource: Al 1486.6 mono
XrayPower: 350.00 W
NeutralizerEnergy: 0.0 eV
NeutralizerCurrent: 0.0 mA
SourceAnalyserAngle: 90.0 d
AnalyserMode: FAT
AnalyserWorkFcn: 4.5 eV
IntensityRecal: no
IntensityCalCoeff: 24.500 0.207
EnergyRecal: no
EnergyReference: none 0.0
SputterIon: 3He
SputterEnergy: 3.000 keV
SputterCurrent: 0.0 nA
SputterRaster: 10.0 0.0 um
PreAcqSputterTime: 10 s
PreAcqSputterRate: 1.0 A/s
NoSpectralReg: 4
SpectralRegDef: 1 1 C1 6 140 -0.1000 294.0 280.0 292.0 280.0 0.100000 23.50 none
SpectralRegDef: 2 2 Sb1 51 200 -0.1000 545.0 525.0 545.0 525.0 0.100000 23.50 none
SpectralRegDef: 3 3 Cu1 29 500 -0.1000 974.0 924.0 935.0 924.0 0.100000 23.50 none
SpectralRegDef: 4 4 S1 16 200 -0.1000 178.0 158.0 170.0 158.0 0.100000 23.50 none
NoDPDataCyc: 17
NoPreSputterCyc: 2
SputterInterval: 5.000 s
SputterMode: alt
SampleRotation: off
DepthRecal: no
NoSpatialArea: 1
SpatialAreaDef: 1 Full 1 (0.0 0.0 0.0 0.0 0.0)
EOFH
CasaRowLabel:09092210.pro:Sample_Pro_Sb_NativeOxide
CasaRowLabel:09092210.pro:Sample_Pro_Sb_NativeOxide
CasaRowLabel:09092210.pro:Sample_Pro_Sb_NativeOxide
CasaRowLabel:09092210.pro:Sample_Pro_Sb_NativeOxide
CasaRowLabel:09092210.pro:Sample_Pro_Sb_NativeOxide
CasaRowLabel:09092210.pro:Sample_Pro_Sb_NativeOxide
CasaRowLabel:09092210.pro:Sample_Pro_Sb_NativeOxide
CasaRowLabel:09092210.pro:Sample_Pro_Sb_NativeOxide
CasaRowLabel:09092210.pro:Sample_Pro_Sb_NativeOxide
CasaRowLabel:09092210.pro:Sample_Pro_Sb_NativeOxide
CasaRowLabel:09092210.pro:Sample_Pro_Sb_NativeOxide
CasaRowLabel:09092210.pro:Sample_Pro_Sb_NativeOxide
CasaRowLabel:09092210.pro:Sample_Pro_Sb_NativeOxide
CasaRowLabel:09092210.pro:Sample_Pro_Sb_NativeOxide
CasaRowLabel:09092210.pro:Sample_Pro_Sb_NativeOxide
CasaRowLabel:09092210.pro:Sample_Pro_Sb_NativeOxide
CasaRowLabel:09092210.pro:Sample_Pro_Sb_NativeOxide
NORM
REGULAR
4
1
Etch Time
s
0
0
0
0
68
C 1s 1
09092210.pro:Sample_Pro_Sb_NativeOxide
122
9
9
0
0
0
0
13
Casa Info Follows
1
Calib M = 285.0708 A = 285 BE ADD
0
1
CASA region (*C 1s*) (*Shirley*) 1193.3658 1205.8758 0.314 2 0 0 0 -450 0 0 (*C 1s*) 12.011 0 0.314
3
CASA comp (*C 1s*) (*GL(0)*) Area 691.68753 1e-020 9320.1172 -1 1 MFWHM 1.2639166 0.24 6 -1 1 Position 1201.6 1193.3658 1205.8758 -1 1 RSF 0.314 MASS 12.011 INDEX -1 (*C 1s*) CONST (**) UNCORRECTEDRSF 0.314
CASA comp (*C 1s*) (*GL(0)*) Area 276.94732 1e-020 5107.0032 -1 1 MFWHM 1.2639166 0.19857143 4.9642857 0 1 Position 1200.934 1193.3658 1205.8758 -1 1 RSF 0.314 MASS 12.011 INDEX -1 (*C 1s*) CONST (**) UNCORRECTEDRSF 0.314
CASA comp (*C 1s*) (*GL(0)*) Area 326.45004 1e-020 6742.5673 -1 1 MFWHM 1.2639166 0.43857143 10.964286 0 1 Position 1199.8651 1193.3658 1205.8758 -1 1 RSF 0.314 MASS 12.011 INDEX -1 (*C 1s*) CONST (**) UNCORRECTEDRSF 0.314
JRG_KN_SbatCu_addstudies_DW_cPANpol
( 0 m , 0 m , 0 m ) Angle: 45 degrees , 0 degrees
SputterRaster: 10.0 0.0 um
XPS
-10
PHI1486
1486.6
350
1e+037
1e+037
1e+037
1e+037
FAT
23.5
1e+037
4.5
1e+037
1e+037
1e+037
1e+037
1e+037
C
1s
-1
Kinetic Energy
eV
1192.6
0.1
2
Intensity
d
Transmission
d
pulse counting
0.1
1
1e+037
1e+037
1e+037
1e+037
3
ESCAPE DEPTH TYPE
d
0
PHI_AtomicNumber
d
6
PROPAGATION_CONVERGED
d
1
280
0
1
0
1
54
16.6457
64
16.6452
55
16.6447
53
16.6443
63
16.6438
57
16.6433
65
16.6429
53
16.6424
58
16.6419
47
16.6415
60
16.641
56
16.6405
57
16.6401
38
16.6396
56
16.6391
67
16.6387
62
16.6382
70
16.6377
50
16.6373
71
16.6368
43
16.6363
53
16.6359
48
16.6354
53
16.6349
49
16.6345
66
16.634
54
16.6335
53
16.633
66
16.6326
67
16.6321
59
16.6316
57
16.6312
63
16.6307
70
16.6302
64
16.6298
62
16.6293
50
16.6288
54
16.6284
60
16.6279
59
16.6274
61
16.627
63
16.6265
48
16.626
58
16.6256
57
16.6251
50
16.6246
58
16.6242
54
16.6237
58
16.6232
60
16.6228
51
16.6223
85
16.6218
64
16.6214
56
16.6209
52
16.6204
52
16.62
57
16.6195
55
16.619
70
16.6186
59
16.6181
62
16.6176
56
16.6172
62
16.6167
62
16.6162
56
16.6158
76
16.6153
68
16.6148
76
16.6144
83
16.6139
77
16.6134
86
16.613
87
16.6125
84
16.612
85
16.6116
73
16.6111
85
16.6106
102
16.6102
87
16.6097
96
16.6092
93
16.6088
84
16.6083
88
16.6079
124
16.6074
102
16.6069
116
16.6065
99
16.606
120
16.6055
124
16.6051
116
16.6046
121
16.6041
104
16.6037
134
16.6032
102
16.6027
95
16.6023
93
16.6018
79
16.6013
76
16.6009
74
16.6004
82
16.5999
68
16.5995
59
16.599
69
16.5985
61
16.5981
49
16.5976
64
16.5972
57
16.5967
60
16.5962
55
16.5958
56
16.5953
51
16.5948
60
16.5944
63
16.5939
57
16.5934
66
16.593
63
16.5925
52
16.592
57
16.5916
65
16.5911
69
16.5907
55
16.5902
56
16.5897
58
16.5893
43
16.5888
52
16.5883
50
16.5879
58
16.5874
44
16.5869
56
16.5865
54
16.586
61
16.5855
42
16.5851
59
16.5846
52
16.5842
56
16.5837
54
16.5832
50
16.5828
63
16.5823
57
16.5818
54
16.5814
69
16.5809
C 1s 2
09092210.pro:Sample_Pro_Sb_NativeOxide
122
9
9
0
0
0
0
12
Casa Info Follows
1
Calib M = 285.3496 A = 285 BE ADD
0
1
CASA region (*C 1s*) (*Shirley*) 1193.8508 1206.6459 0.314 2 0 0 0 -450 0 0 (*C 1s*) 12.011 0 0.314
2
CASA comp (*C 1s*) (*GL(0)*) Area 1022.3066 1e-020 9320.1172 -1 1 MFWHM 1.6319417 0.24 6 -1 1 Position 1201.6 1193.8508 1206.1546 -1 1 RSF 0.314 MASS 12.011 INDEX -1 (*C 1s*) CONST (**) UNCORRECTEDRSF 0.314
CASA comp (*C 1s*) (*GL(0)*) Area 320.33661 1e-020 5107.0032 -1 1 MFWHM 1.6319417 0.19857143 4.9642857 0 1 Position 1199.9779 1193.8508 1206.1546 -1 1 RSF 0.314 MASS 12.011 INDEX -1 (*C 1s*) CONST (**) UNCORRECTEDRSF 0.314
JRG_KN_SbatCu_addstudies_DW_cPANpol
( 0 m , 0 m , 0 m ) Angle: 45 degrees , 0 degrees
SputterRaster: 10.0 0.0 um
XPS
-5
PHI1486
1486.6
350
1e+037
1e+037
1e+037
1e+037
FAT
23.5
1e+037
4.5
1e+037
1e+037
1e+037
1e+037
1e+037
C
1s
-1
Kinetic Energy
eV
1192.6
0.1
2
Intensity
d
Transmission
d
pulse counting
0.1
1
1e+037
1e+037
1e+037
1e+037
4
ESCAPE DEPTH TYPE
d
0
PHI_AtomicNumber
d
6
MFP Exponent
d
0
PROPAGATION_CONVERGED
d
1
280
0
1
0
1
61
16.6457
59
16.6452
55
16.6447
59
16.6443
46
16.6438
63
16.6433
53
16.6429
50
16.6424
56
16.6419
44
16.6415
64
16.641
71
16.6405
52
16.6401
66
16.6396
73
16.6391
63
16.6387
60
16.6382
65
16.6377
65
16.6373
64
16.6368
83
16.6363
47
16.6359
69
16.6354
59
16.6349
58
16.6345
53
16.634
58
16.6335
48
16.633
72
16.6326
46
16.6321
53
16.6316
57
16.6312
61
16.6307
66
16.6302
61
16.6298
61
16.6293
61
16.6288
64
16.6284
53
16.6279
54
16.6274
59
16.627
59
16.6265
70
16.626
60
16.6256
61
16.6251
67
16.6246
65
16.6242
74
16.6237
64
16.6232
62
16.6228
56
16.6223
67
16.6218
68
16.6214
61
16.6209
69
16.6204
46
16.62
63
16.6195
67
16.619
76
16.6186
66
16.6181
80
16.6176
56
16.6172
80
16.6167
74
16.6162
59
16.6158
52
16.6153
77
16.6148
65
16.6144
84
16.6139
77
16.6134
97
16.613
81
16.6125
69
16.612
86
16.6116
81
16.6111
97
16.6106
89
16.6102
95
16.6097
95
16.6092
103
16.6088
121
16.6083
96
16.6079
93
16.6074
111
16.6069
102
16.6065
117
16.606
111
16.6055
115
16.6051
126
16.6046
111
16.6041
118
16.6037
108
16.6032
107
16.6027
96
16.6023
80
16.6018
71
16.6013
77
16.6009
73
16.6004
62
16.5999
60
16.5995
61
16.599
59
16.5985
57
16.5981
63
16.5976
57
16.5972
69
16.5967
53
16.5962
54
16.5958
57
16.5953
64
16.5948
60
16.5944
53
16.5939
60
16.5934
68
16.593
48
16.5925
54
16.592
61
16.5916
56
16.5911
57
16.5907
53
16.5902
49
16.5897
50
16.5893
55
16.5888
60
16.5883
64
16.5879
62
16.5874
71
16.5869
44
16.5865
66
16.586
50
16.5855
57
16.5851
67
16.5846
54
16.5842
44
16.5837
59
16.5832
48
16.5828
58
16.5823
56
16.5818
47
16.5814
51
16.5809
C 1s 3
09092210.pro:Sample_Pro_Sb_NativeOxide
122
9
9
0
0
0
0
8
Casa Info Follows
0
0
0
0
JRG_KN_SbatCu_addstudies_DW_cPANpol
( 0 m , 0 m , 0 m ) Angle: 45 degrees , 0 degrees
SputterRaster: 10.0 0.0 um
XPS
300
PHI1486
1486.6
350
1e+037
1e+037
1e+037
1e+037
FAT
23.5
1e+037
4.5
1e+037
1e+037
1e+037
1e+037
1e+037
C
1s
-1
Kinetic Energy
eV
1192.6
0.1
2
Intensity
d
Transmission
d
pulse counting
0.1
1
1e+037
1e+037
1e+037
1e+037
2
ESCAPE DEPTH TYPE
d
0
PHI_AtomicNumber
d
6
280
0
1
0
1
48
16.6457
52
16.6452
57
16.6447
46
16.6443
57
16.6438
46
16.6433
48
16.6429
48
16.6424
49
16.6419
63
16.6415
57
16.641
66
16.6405
55
16.6401
58
16.6396
56
16.6391
71
16.6387
45
16.6382
61
16.6377
60
16.6373
55
16.6368
72
16.6363
48
16.6359
62
16.6354
42
16.6349
59
16.6345
54
16.634
60
16.6335
48
16.633
58
16.6326
56
16.6321
69
16.6316
70
16.6312
65
16.6307
54
16.6302
51
16.6298
49
16.6293
69
16.6288
50
16.6284
65
16.6279
46
16.6274
54
16.627
55
16.6265
50
16.626
49
16.6256
38
16.6251
68
16.6246
46
16.6242
58
16.6237
57
16.6232
49
16.6228
50
16.6223
61
16.6218
59
16.6214
61
16.6209
67
16.6204
70
16.62
58
16.6195
64
16.619
65
16.6186
66
16.6181
74
16.6176
51
16.6172
73
16.6167
58
16.6162
68
16.6158
61
16.6153
56
16.6148
78
16.6144
49
16.6139
65
16.6134
66
16.613
68
16.6125
55
16.612
43
16.6116
65
16.6111
51
16.6106
53
16.6102
56
16.6097
55
16.6092
60
16.6088
62
16.6083
57
16.6079
45
16.6074
70
16.6069
65
16.6065
58
16.606
65
16.6055
54
16.6051
48
16.6046
62
16.6041
62
16.6037
66
16.6032
60
16.6027
61
16.6023
47
16.6018
59
16.6013
60
16.6009
61
16.6004
65
16.5999
60
16.5995
67
16.599
65
16.5985
59
16.5981
50
16.5976
68
16.5972
76
16.5967
70
16.5962
64
16.5958
59
16.5953
63
16.5948
43
16.5944
73
16.5939
55
16.5934
64
16.593
62
16.5925
53
16.592
54
16.5916
68
16.5911
44
16.5907
65
16.5902
60
16.5897
43
16.5893
50
16.5888
47
16.5883
58
16.5879
51
16.5874
55
16.5869
46
16.5865
58
16.586
67
16.5855
72
16.5851
55
16.5846
56
16.5842
58
16.5837
55
16.5832
55
16.5828
66
16.5823
45
16.5818
64
16.5814
47
16.5809
C 1s 4
09092210.pro:Sample_Pro_Sb_NativeOxide
122
9
9
0
0
0
0
8
Casa Info Follows
0
0
0
0
JRG_KN_SbatCu_addstudies_DW_cPANpol
( 0 m , 0 m , 0 m ) Angle: 45 degrees , 0 degrees
SputterRaster: 10.0 0.0 um
XPS
600
PHI1486
1486.6
350
1e+037
1e+037
1e+037
1e+037
FAT
23.5
1e+037
4.5
1e+037
1e+037
1e+037
1e+037
1e+037
C
1s
-1
Kinetic Energy
eV
1192.6
0.1
2
Intensity
d
Transmission
d
pulse counting
0.1
1
1e+037
1e+037
1e+037
1e+037
2
ESCAPE DEPTH TYPE
d
0
PHI_AtomicNumber
d
6
280
0
1
0
1
36
16.6457
43
16.6452
41
16.6447
36
16.6443
47
16.6438
60
16.6433
50
16.6429
55
16.6424
64
16.6419
47
16.6415
62
16.641
51
16.6405
57
16.6401
49
16.6396
59
16.6391
62
16.6387
62
16.6382
51
16.6377
60
16.6373
55
16.6368
59
16.6363
65
16.6359
57
16.6354
59
16.6349
49
16.6345
45
16.634
51
16.6335
63
16.633
59
16.6326
62
16.6321
58
16.6316
80
16.6312
60
16.6307
70
16.6302
52
16.6298
68
16.6293
63
16.6288
45
16.6284
54
16.6279
54
16.6274
51
16.627
74
16.6265
60
16.626
62
16.6256
46
16.6251
63
16.6246
59
16.6242
56
16.6237
63
16.6232
59
16.6228
54
16.6223
73
16.6218
45
16.6214
47
16.6209
53
16.6204
67
16.62
53
16.6195
72
16.619
52
16.6186
60
16.6181
57
16.6176
63
16.6172
57
16.6167
59
16.6162
61
16.6158
57
16.6153
64
16.6148
62
16.6144
65
16.6139
55
16.6134
51
16.613
51
16.6125
51
16.612
67
16.6116
59
16.6111
56
16.6106
63
16.6102
51
16.6097
67
16.6092
50
16.6088
64
16.6083
47
16.6079
64
16.6074
49
16.6069
68
16.6065
47
16.606
61
16.6055
56
16.6051
69
16.6046
58
16.6041
62
16.6037
59
16.6032
71
16.6027
73
16.6023
59
16.6018
70
16.6013
66
16.6009
68
16.6004
63
16.5999
56
16.5995
54
16.599
62
16.5985
62
16.5981
53
16.5976
70
16.5972
62
16.5967
58
16.5962
47
16.5958
70
16.5953
56
16.5948
65
16.5944
53
16.5939
57
16.5934
55
16.593
57
16.5925
64
16.592
65
16.5916
56
16.5911
51
16.5907
66
16.5902
55
16.5897
47
16.5893
60
16.5888
61
16.5883
45
16.5879
55
16.5874
49
16.5869
63
16.5865
66
16.586
74
16.5855
54
16.5851
76
16.5846
53
16.5842
55
16.5837
52
16.5832
47
16.5828
60
16.5823
64
16.5818
50
16.5814
65
16.5809
C 1s 5
09092210.pro:Sample_Pro_Sb_NativeOxide
122
9
9
0
0
0
0
8
Casa Info Follows
0
0
0
0
JRG_KN_SbatCu_addstudies_DW_cPANpol
( 0 m , 0 m , 0 m ) Angle: 45 degrees , 0 degrees
SputterRaster: 10.0 0.0 um
XPS
900
PHI1486
1486.6
350
1e+037
1e+037
1e+037
1e+037
FAT
23.5
1e+037
4.5
1e+037
1e+037
1e+037
1e+037
1e+037
C
1s
-1
Kinetic Energy
eV
1192.6
0.1
2
Intensity
d
Transmission
d
pulse counting
0.1
1
1e+037
1e+037
1e+037
1e+037
2
ESCAPE DEPTH TYPE
d
0
PHI_AtomicNumber
d
6
280
0
1
0
1
32
16.6457
30
16.6452
37
16.6447
42
16.6443
42
16.6438
42
16.6433
58
16.6429
58
16.6424
58
16.6419
63
16.6415
71
16.641
59
16.6405
66
16.6401
75
16.6396
54
16.6391
52
16.6387
62
16.6382
66
16.6377
62
16.6373
68
16.6368
59
16.6363
59
16.6359
53
16.6354
70
16.6349
60
16.6345
72
16.634
72
16.6335
56
16.633
59
16.6326
54
16.6321
64
16.6316
66
16.6312
58
16.6307
58
16.6302
65
16.6298
43
16.6293
59
16.6288
46
16.6284
48
16.6279
58
16.6274
63
16.627
54
16.6265
59
16.626
60
16.6256
54
16.6251
65
16.6246
57
16.6242
55
16.6237
55
16.6232
52
16.6228
59
16.6223
64
16.6218
63
16.6214
55
16.6209
66
16.6204
54
16.62
60
16.6195
65
16.619
59
16.6186
78
16.6181
62
16.6176
58
16.6172
64
16.6167
54
16.6162
62
16.6158
59
16.6153
60
16.6148
70
16.6144
63
16.6139
64
16.6134
53
16.613
51
16.6125
68
16.612
56
16.6116
58
16.6111
55
16.6106
56
16.6102
54
16.6097
68
16.6092
59
16.6088
68
16.6083
61
16.6079
60
16.6074
50
16.6069
60
16.6065
52
16.606
50
16.6055
57
16.6051
60
16.6046
54
16.6041
63
16.6037
54
16.6032
58
16.6027
50
16.6023
48
16.6018
62
16.6013
82
16.6009
71
16.6004
63
16.5999
61
16.5995
58
16.599
60
16.5985
60
16.5981
57
16.5976
60
16.5972
66
16.5967
75
16.5962
53
16.5958
70
16.5953
48
16.5948
62
16.5944
49
16.5939
60
16.5934
59
16.593
64
16.5925
60
16.592
54
16.5916
54
16.5911
45
16.5907
57
16.5902
62
16.5897
59
16.5893
66
16.5888
60
16.5883
67
16.5879
56
16.5874
48
16.5869
62
16.5865
53
16.586
60
16.5855
68
16.5851
70
16.5846
69
16.5842
62
16.5837
55
16.5832
41
16.5828
53
16.5823
62
16.5818
59
16.5814
54
16.5809
C 1s 6
09092210.pro:Sample_Pro_Sb_NativeOxide
122
9
9
0
0
0
0
8
Casa Info Follows
0
0
0
0
JRG_KN_SbatCu_addstudies_DW_cPANpol
( 0 m , 0 m , 0 m ) Angle: 45 degrees , 0 degrees
SputterRaster: 10.0 0.0 um
XPS
1200
PHI1486
1486.6
350
1e+037
1e+037
1e+037
1e+037
FAT
23.5
1e+037
4.5
1e+037
1e+037
1e+037
1e+037
1e+037
C
1s
-1
Kinetic Energy
eV
1192.6
0.1
2
Intensity
d
Transmission
d
pulse counting
0.1
1
1e+037
1e+037
1e+037
1e+037
2
ESCAPE DEPTH TYPE
d
0
PHI_AtomicNumber
d
6
280
0
1
0
1
35
16.6457
46
16.6452
33
16.6447
31
16.6443
58
16.6438
40
16.6433
56
16.6429
48
16.6424
62
16.6419
51
16.6415
51
16.641
59
16.6405
56
16.6401
61
16.6396
57
16.6391
67
16.6387
63
16.6382
49
16.6377
52
16.6373
61
16.6368
48
16.6363
62
16.6359
70
16.6354
63
16.6349
59
16.6345
66
16.634
48
16.6335
65
16.633
51
16.6326
57
16.6321
56
16.6316
62
16.6312
62
16.6307
63
16.6302
57
16.6298
64
16.6293
56
16.6288
53
16.6284
66
16.6279
59
16.6274
55
16.627
65
16.6265
52
16.626
62
16.6256
65
16.6251
60
16.6246
80
16.6242
49
16.6237
64
16.6232
58
16.6228
60
16.6223
49
16.6218
77
16.6214
58
16.6209
72
16.6204
66
16.62
57
16.6195
56
16.619
62
16.6186
56
16.6181
51
16.6176
51
16.6172
59
16.6167
52
16.6162
54
16.6158
63
16.6153
54
16.6148
72
16.6144
64
16.6139
67
16.6134
60
16.613
69
16.6125
63
16.612
73
16.6116
60
16.6111
50
16.6106
57
16.6102
48
16.6097
54
16.6092
60
16.6088
63
16.6083
63
16.6079
41
16.6074
66
16.6069
74
16.6065
61
16.606
63
16.6055
64
16.6051
61
16.6046
63
16.6041
54
16.6037
71
16.6032
54
16.6027
68
16.6023
62
16.6018
78
16.6013
73
16.6009
65
16.6004
57
16.5999
60
16.5995
64
16.599
60
16.5985
59
16.5981
72
16.5976
58
16.5972
63
16.5967
61
16.5962
67
16.5958
65
16.5953
63
16.5948
59
16.5944
69
16.5939
52
16.5934
47
16.593
53
16.5925
55
16.592
66
16.5916
57
16.5911
59
16.5907
63
16.5902
65
16.5897
55
16.5893
59
16.5888
62
16.5883
53
16.5879
51
16.5874
53
16.5869
47
16.5865
62
16.586
46
16.5855
54
16.5851
56
16.5846
61
16.5842
75
16.5837
60
16.5832
60
16.5828
70
16.5823
64
16.5818
72
16.5814
73
16.5809
C 1s 7
09092210.pro:Sample_Pro_Sb_NativeOxide
122
9
9
0
0
0
0
8
Casa Info Follows
0
0
0
0
JRG_KN_SbatCu_addstudies_DW_cPANpol
( 0 m , 0 m , 0 m ) Angle: 45 degrees , 0 degrees
SputterRaster: 10.0 0.0 um
XPS
1500
PHI1486
1486.6
350
1e+037
1e+037
1e+037
1e+037
FAT
23.5
1e+037
4.5
1e+037
1e+037
1e+037
1e+037
1e+037
C
1s
-1
Kinetic Energy
eV
1192.6
0.1
2
Intensity
d
Transmission
d
pulse counting
0.1
1
1e+037
1e+037
1e+037
1e+037
2
ESCAPE DEPTH TYPE
d
0
PHI_AtomicNumber
d
6
280
0
1
0
1
39
16.6457
45
16.6452
37
16.6447
52
16.6443
56
16.6438
60
16.6433
58
16.6429
62
16.6424
50
16.6419
59
16.6415
54
16.641
44
16.6405
55
16.6401
49
16.6396
56
16.6391
61
16.6387
50
16.6382
60
16.6377
51
16.6373
60
16.6368
47
16.6363
52
16.6359
52
16.6354
58
16.6349
65
16.6345
67
16.634
54
16.6335
60
16.633
48
16.6326
63
16.6321
61
16.6316
48
16.6312
63
16.6307
49
16.6302
62
16.6298
52
16.6293
68
16.6288
62
16.6284
47
16.6279
59
16.6274
60
16.627
61
16.6265
71
16.626
58
16.6256
57
16.6251
50
16.6246
61
16.6242
62
16.6237
66
16.6232
54
16.6228
65
16.6223
50
16.6218
59
16.6214
70
16.6209
58
16.6204
51
16.62
61
16.6195
53
16.619
73
16.6186
57
16.6181
60
16.6176
55
16.6172
49
16.6167
50
16.6162
55
16.6158
50
16.6153
66
16.6148
49
16.6144
64
16.6139
55
16.6134
76
16.613
69
16.6125
64
16.612
42
16.6116
40
16.6111
57
16.6106
52
16.6102
60
16.6097
54
16.6092
59
16.6088
69
16.6083
53
16.6079
52
16.6074
57
16.6069
65
16.6065
50
16.606
56
16.6055
59
16.6051
69
16.6046
54
16.6041
75
16.6037
55
16.6032
68
16.6027
50
16.6023
65
16.6018
62
16.6013
57
16.6009
69
16.6004
40
16.5999
57
16.5995
61
16.599
58
16.5985
48
16.5981
62
16.5976
54
16.5972
63
16.5967
71
16.5962
61
16.5958
69
16.5953
59
16.5948
62
16.5944
69
16.5939
55
16.5934
52
16.593
47
16.5925
64
16.592
62
16.5916
57
16.5911
46
16.5907
59
16.5902
82
16.5897
62
16.5893
54
16.5888
49
16.5883
53
16.5879
58
16.5874
64
16.5869
60
16.5865
63
16.586
55
16.5855
49
16.5851
64
16.5846
72
16.5842
75
16.5837
62
16.5832
61
16.5828
57
16.5823
59
16.5818
69
16.5814
66
16.5809
C 1s 8
09092210.pro:Sample_Pro_Sb_NativeOxide
122
9
9
0
0
0
0
8
Casa Info Follows
0
0
0
0
JRG_KN_SbatCu_addstudies_DW_cPANpol
( 0 m , 0 m , 0 m ) Angle: 45 degrees , 0 degrees
SputterRaster: 10.0 0.0 um
XPS
1800
PHI1486
1486.6
350
1e+037
1e+037
1e+037
1e+037
FAT
23.5
1e+037
4.5
1e+037
1e+037
1e+037
1e+037
1e+037
C
1s
-1
Kinetic Energy
eV
1192.6
0.1
2
Intensity
d
Transmission
d
pulse counting
0.1
1
1e+037
1e+037
1e+037
1e+037
2
ESCAPE DEPTH TYPE
d
0
PHI_AtomicNumber
d
6
280
0
1
0
1
33
16.6457
38
16.6452
53
16.6447
40
16.6443
49
16.6438
42
16.6433
59
16.6429
37
16.6424
54
16.6419
68
16.6415
50
16.641
69
16.6405
58
16.6401
66
16.6396
57
16.6391
46
16.6387
57
16.6382
45
16.6377
51
16.6373
59
16.6368
64
16.6363
59
16.6359
58
16.6354
41
16.6349
41
16.6345
67
16.634
54
16.6335
61
16.633
56
16.6326
61
16.6321
57
16.6316
64
16.6312
59
16.6307
47
16.6302
55
16.6298
56
16.6293
53
16.6288
53
16.6284
63
16.6279
52
16.6274
55
16.627
61
16.6265
51
16.626
46
16.6256
55
16.6251
48
16.6246
63
16.6242
60
16.6237
61
16.6232
63
16.6228
54
16.6223
63
16.6218
51
16.6214
62
16.6209
51
16.6204
46
16.62
56
16.6195
57
16.619
56
16.6186
59
16.6181
59
16.6176
59
16.6172
72
16.6167
42
16.6162
60
16.6158
51
16.6153
56
16.6148
46
16.6144
59
16.6139
59
16.6134
59
16.613
56
16.6125
62
16.612
56
16.6116
64
16.6111
59
16.6106
65
16.6102
56
16.6097
53
16.6092
54
16.6088
61
16.6083
56
16.6079
63
16.6074
50
16.6069
57
16.6065
53
16.606
66
16.6055
54
16.6051
72
16.6046
48
16.6041
53
16.6037
56
16.6032
63
16.6027
67
16.6023
56
16.6018
58
16.6013
58
16.6009
57
16.6004
68
16.5999
66
16.5995
68
16.599
61
16.5985
68
16.5981
60
16.5976
65
16.5972
60
16.5967
61
16.5962
60
16.5958
49
16.5953
52
16.5948
60
16.5944
57
16.5939
64
16.5934
56
16.593
60
16.5925
53
16.592
57
16.5916
73
16.5911
61
16.5907
51
16.5902
63
16.5897
50
16.5893
66
16.5888
63
16.5883
51
16.5879
63
16.5874
53
16.5869
63
16.5865
57
16.586
51
16.5855
56
16.5851
65
16.5846
79
16.5842
62
16.5837
57
16.5832
45
16.5828
47
16.5823
48
16.5818
59
16.5814
49
16.5809
C 1s 9
09092210.pro:Sample_Pro_Sb_NativeOxide
122
9
9
0
0
0
0
8
Casa Info Follows
0
0
0
0
JRG_KN_SbatCu_addstudies_DW_cPANpol
( 0 m , 0 m , 0 m ) Angle: 45 degrees , 0 degrees
SputterRaster: 10.0 0.0 um
XPS
2100
PHI1486
1486.6
350
1e+037
1e+037
1e+037
1e+037
FAT
23.5
1e+037
4.5
1e+037
1e+037
1e+037
1e+037
1e+037
C
1s
-1
Kinetic Energy
eV
1192.6
0.1
2
Intensity
d
Transmission
d
pulse counting
0.1
1
1e+037
1e+037
1e+037
1e+037
2
ESCAPE DEPTH TYPE
d
0
PHI_AtomicNumber
d
6
280
0
1
0
1
34
16.6457
45
16.6452
30
16.6447
44
16.6443
45
16.6438
62
16.6433
53
16.6429
53
16.6424
48
16.6419
46
16.6415
55
16.641
55
16.6405
58
16.6401
61
16.6396
56
16.6391
60
16.6387
47
16.6382
73
16.6377
61
16.6373
59
16.6368
52
16.6363
53
16.6359
52
16.6354
48
16.6349
50
16.6345
56
16.634
70
16.6335
65
16.633
59
16.6326
53
16.6321
66
16.6316
59
16.6312
65
16.6307
60
16.6302
65
16.6298
50
16.6293
53
16.6288
62
16.6284
68
16.6279
54
16.6274
49
16.627
50
16.6265
76
16.626
51
16.6256
74
16.6251
73
16.6246
66
16.6242
56
16.6237
53
16.6232
57
16.6228
70
16.6223
52
16.6218
61
16.6214
54
16.6209
64
16.6204
67
16.62
59
16.6195
55
16.619
64
16.6186
56
16.6181
63
16.6176
59
16.6172
43
16.6167
69
16.6162
40
16.6158
73
16.6153
50
16.6148
58
16.6144
56
16.6139
61
16.6134
73
16.613
52
16.6125
65
16.612
54
16.6116
55
16.6111
68
16.6106
56
16.6102
66
16.6097
49
16.6092
52
16.6088
50
16.6083
68
16.6079
56
16.6074
58
16.6069
59
16.6065
58
16.606
65
16.6055
51
16.6051
51
16.6046
49
16.6041
70
16.6037
55
16.6032
48
16.6027
61
16.6023
51
16.6018
61
16.6013
54
16.6009
58
16.6004
73
16.5999
55
16.5995
66
16.599
61
16.5985
57
16.5981
60
16.5976
56
16.5972
48
16.5967
61
16.5962
56
16.5958
58
16.5953
66
16.5948
65
16.5944
61
16.5939
65
16.5934
57
16.593
55
16.5925
56
16.592
70
16.5916
65
16.5911
58
16.5907
51
16.5902
57
16.5897
55
16.5893
56
16.5888
54
16.5883
44
16.5879
71
16.5874
64
16.5869
57
16.5865
59
16.586
49
16.5855
55
16.5851
55
16.5846
67
16.5842
60
16.5837
66
16.5832
55
16.5828
56
16.5823
64
16.5818
57
16.5814
59
16.5809
C 1s 10
09092210.pro:Sample_Pro_Sb_NativeOxide
122
9
9
0
0
0
0
8
Casa Info Follows
0
0
0
0
JRG_KN_SbatCu_addstudies_DW_cPANpol
( 0 m , 0 m , 0 m ) Angle: 45 degrees , 0 degrees
SputterRaster: 10.0 0.0 um
XPS
2400
PHI1486
1486.6
350
1e+037
1e+037
1e+037
1e+037
FAT
23.5
1e+037
4.5
1e+037
1e+037
1e+037
1e+037
1e+037
C
1s
-1
Kinetic Energy
eV
1192.6
0.1
2
Intensity
d
Transmission
d
pulse counting
0.1
1
1e+037
1e+037
1e+037
1e+037
2
ESCAPE DEPTH TYPE
d
0
PHI_AtomicNumber
d
6
280
0
1
0
1
34
16.6457
30
16.6452
48
16.6447
33
16.6443
53
16.6438
60
16.6433
58
16.6429
56
16.6424
65
16.6419
57
16.6415
58
16.641
53
16.6405
76
16.6401
53
16.6396
62
16.6391
71
16.6387
63
16.6382
56
16.6377
43
16.6373
67
16.6368
61
16.6363
44
16.6359
55
16.6354
66
16.6349
63
16.6345
53
16.634
58
16.6335
59
16.633
69
16.6326
52
16.6321
52
16.6316
49
16.6312
56
16.6307
56
16.6302
60
16.6298
54
16.6293
69
16.6288
58
16.6284
53
16.6279
40
16.6274
67
16.627
65
16.6265
56
16.626
45
16.6256
60
16.6251
52
16.6246
62
16.6242
54
16.6237
64
16.6232
68
16.6228
44
16.6223
46
16.6218
61
16.6214
37
16.6209
54
16.6204
50
16.62
55
16.6195
58
16.619
58
16.6186
64
16.6181
59
16.6176
72
16.6172
61
16.6167
62
16.6162
65
16.6158
62
16.6153
54
16.6148
71
16.6144
54
16.6139
64
16.6134
77
16.613
66
16.6125
55
16.612
69
16.6116
56
16.6111
78
16.6106
78
16.6102
68
16.6097
61
16.6092
50
16.6088
57
16.6083
50
16.6079
54
16.6074
57
16.6069
73
16.6065
64
16.606
62
16.6055
44
16.6051
52
16.6046
53
16.6041
64
16.6037
61
16.6032
57
16.6027
55
16.6023
57
16.6018
54
16.6013
48
16.6009
57
16.6004
56
16.5999
61
16.5995
56
16.599
68
16.5985
72
16.5981
56
16.5976
54
16.5972
54
16.5967
58
16.5962
57
16.5958
65
16.5953
55
16.5948
78
16.5944
63
16.5939
59
16.5934
69
16.593
61
16.5925
49
16.592
64
16.5916
62
16.5911
65
16.5907
66
16.5902
58
16.5897
72
16.5893
51
16.5888
67
16.5883
64
16.5879
50
16.5874
68
16.5869
62
16.5865
60
16.586
60
16.5855
58
16.5851
60
16.5846
63
16.5842
61
16.5837
60
16.5832
49
16.5828
58
16.5823
59
16.5818
62
16.5814
60
16.5809
C 1s 11
09092210.pro:Sample_Pro_Sb_NativeOxide
122
9
9
0
0
0
0
8
Casa Info Follows
0
0
0
0
JRG_KN_SbatCu_addstudies_DW_cPANpol
( 0 m , 0 m , 0 m ) Angle: 45 degrees , 0 degrees
SputterRaster: 10.0 0.0 um
XPS
2700
PHI1486
1486.6
350
1e+037
1e+037
1e+037
1e+037
FAT
23.5
1e+037
4.5
1e+037
1e+037
1e+037
1e+037
1e+037
C
1s
-1
Kinetic Energy
eV
1192.6
0.1
2
Intensity
d
Transmission
d
pulse counting
0.1
1
1e+037
1e+037
1e+037
1e+037
2
ESCAPE DEPTH TYPE
d
0
PHI_AtomicNumber
d
6
280
0
1
0
1
43
16.6457
37
16.6452
43
16.6447
41
16.6443
38
16.6438
52
16.6433
46
16.6429
63
16.6424
62
16.6419
63
16.6415
56
16.641
53
16.6405
67
16.6401
64
16.6396
41
16.6391
43
16.6387
59
16.6382
51
16.6377
54
16.6373
48
16.6368
75
16.6363
56
16.6359
64
16.6354
53
16.6349
54
16.6345
46
16.634
57
16.6335
39
16.633
48
16.6326
63
16.6321
47
16.6316
58
16.6312
56
16.6307
55
16.6302
59
16.6298
66
16.6293
60
16.6288
64
16.6284
58
16.6279
39
16.6274
66
16.627
50
16.6265
66
16.626
60
16.6256
61
16.6251
69
16.6246
57
16.6242
59
16.6237
63
16.6232
62
16.6228
62
16.6223
55
16.6218
55
16.6214
62
16.6209
56
16.6204
59
16.62
40
16.6195
56
16.619
55
16.6186
72
16.6181
58
16.6176
58
16.6172
60
16.6167
54
16.6162
71
16.6158
62
16.6153
62
16.6148
59
16.6144
49
16.6139
51
16.6134
54
16.613
60
16.6125
61
16.612
54
16.6116
52
16.6111
61
16.6106
44
16.6102
80
16.6097
56
16.6092
59
16.6088
41
16.6083
52
16.6079
58
16.6074
58
16.6069
38
16.6065
74
16.606
52
16.6055
54
16.6051
53
16.6046
60
16.6041
56
16.6037
48
16.6032
59
16.6027
46
16.6023
61
16.6018
62
16.6013
54
16.6009
61
16.6004
62
16.5999
52
16.5995
50
16.599
66
16.5985
57
16.5981
56
16.5976
56
16.5972
60
16.5967
61
16.5962
54
16.5958
67
16.5953
64
16.5948
53
16.5944
67
16.5939
57
16.5934
60
16.593
64
16.5925
64
16.592
59
16.5916
63
16.5911
61
16.5907
55
16.5902
69
16.5897
57
16.5893
66
16.5888
71
16.5883
67
16.5879
63
16.5874
67
16.5869
59
16.5865
61
16.586
44
16.5855
67
16.5851
51
16.5846
59
16.5842
68
16.5837
55
16.5832
62
16.5828
59
16.5823
51
16.5818
60
16.5814
54
16.5809
C 1s 12
09092210.pro:Sample_Pro_Sb_NativeOxide
122
9
9
0
0
0
0
8
Casa Info Follows
0
0
0
0
JRG_KN_SbatCu_addstudies_DW_cPANpol
( 0 m , 0 m , 0 m ) Angle: 45 degrees , 0 degrees
SputterRaster: 10.0 0.0 um
XPS
3000
PHI1486
1486.6
350
1e+037
1e+037
1e+037
1e+037
FAT
23.5
1e+037
4.5
1e+037
1e+037
1e+037
1e+037
1e+037
C
1s
-1
Kinetic Energy
eV
1192.6
0.1
2
Intensity
d
Transmission
d
pulse counting
0.1
1
1e+037
1e+037
1e+037
1e+037
2
ESCAPE DEPTH TYPE
d
0
PHI_AtomicNumber
d
6
280
0
1
0
1
39
16.6457
39
16.6452
44
16.6447
46
16.6443
47
16.6438
45
16.6433
45
16.6429
47
16.6424
52
16.6419
44
16.6415
43
16.641
53
16.6405
35
16.6401
45
16.6396
74
16.6391
53
16.6387
62
16.6382
60
16.6377
57
16.6373
59
16.6368
55
16.6363
50
16.6359
39
16.6354
52
16.6349
46
16.6345
45
16.634
67
16.6335
52
16.633
68
16.6326
55
16.6321
54
16.6316
71
16.6312
42
16.6307
52
16.6302
66
16.6298
58
16.6293
69
16.6288
60
16.6284
67
16.6279
58
16.6274
69
16.627
47
16.6265
56
16.626
57
16.6256
45
16.6251
49
16.6246
48
16.6242
57
16.6237
52
16.6232
49
16.6228
42
16.6223
78
16.6218
62
16.6214
57
16.6209
59
16.6204
64
16.62
74
16.6195
57
16.619
55
16.6186
58
16.6181
58
16.6176
66
16.6172
76
16.6167
48
16.6162
73
16.6158
50
16.6153
50
16.6148
66
16.6144
46
16.6139
62
16.6134
59
16.613
52
16.6125
40
16.612
61
16.6116
50
16.6111
50
16.6106
49
16.6102
49
16.6097
61
16.6092
47
16.6088
52
16.6083
57
16.6079
49
16.6074
61
16.6069
60
16.6065
63
16.606
55
16.6055
50
16.6051
58
16.6046
46
16.6041
62
16.6037
50
16.6032
62
16.6027
65
16.6023
56
16.6018
65
16.6013
65
16.6009
67
16.6004
55
16.5999
50
16.5995
47
16.599
48
16.5985
72
16.5981
62
16.5976
54
16.5972
53
16.5967
57
16.5962
54
16.5958
73
16.5953
71
16.5948
70
16.5944
50
16.5939
61
16.5934
57
16.593
59
16.5925
59
16.592
58
16.5916
55
16.5911
50
16.5907
60
16.5902
66
16.5897
57
16.5893
53
16.5888
48
16.5883
59
16.5879
50
16.5874
45
16.5869
68
16.5865
66
16.586
63
16.5855
61
16.5851
56
16.5846
69
16.5842
50
16.5837
59
16.5832
50
16.5828
71
16.5823
63
16.5818
72
16.5814
46
16.5809
C 1s 13
09092210.pro:Sample_Pro_Sb_NativeOxide
122
9
9
0
0
0
0
8
Casa Info Follows
0
0
0
0
JRG_KN_SbatCu_addstudies_DW_cPANpol
( 0 m , 0 m , 0 m ) Angle: 45 degrees , 0 degrees
SputterRaster: 10.0 0.0 um
XPS
3300
PHI1486
1486.6
350
1e+037
1e+037
1e+037
1e+037
FAT
23.5
1e+037
4.5
1e+037
1e+037
1e+037
1e+037
1e+037
C
1s
-1
Kinetic Energy
eV
1192.6
0.1
2
Intensity
d
Transmission
d
pulse counting
0.1
1
1e+037
1e+037
1e+037
1e+037
2
ESCAPE DEPTH TYPE
d
0
PHI_AtomicNumber
d
6
280
0
1
0
1
52
16.6457
40
16.6452
36
16.6447
51
16.6443
43
16.6438
40
16.6433
64
16.6429
45
16.6424
64
16.6419
64
16.6415
59
16.641
53
16.6405
55
16.6401
56
16.6396
53
16.6391
62
16.6387
52
16.6382
61
16.6377
64
16.6373
60
16.6368
48
16.6363
61
16.6359
45
16.6354
39
16.6349
52
16.6345
55
16.634
56
16.6335
66
16.633
60
16.6326
42
16.6321
64
16.6316
46
16.6312
64
16.6307
59
16.6302
58
16.6298
67
16.6293
65
16.6288
56
16.6284
60
16.6279
63
16.6274
50
16.627
58
16.6265
65
16.626
61
16.6256
51
16.6251
48
16.6246
67
16.6242
56
16.6237
60
16.6232
63
16.6228
61
16.6223
56
16.6218
51
16.6214
41
16.6209
70
16.6204
64
16.62
67
16.6195
65
16.619
63
16.6186
54
16.6181
47
16.6176
54
16.6172
60
16.6167
69
16.6162
57
16.6158
47
16.6153
47
16.6148
66
16.6144
60
16.6139
64
16.6134
58
16.613
47
16.6125
40
16.612
45
16.6116
57
16.6111
50
16.6106
45
16.6102
63
16.6097
60
16.6092
56
16.6088
63
16.6083
61
16.6079
58
16.6074
49
16.6069
68
16.6065
50
16.606
61
16.6055
63
16.6051
58
16.6046
56
16.6041
55
16.6037
64
16.6032
57
16.6027
47
16.6023
53
16.6018
57
16.6013
52
16.6009
55
16.6004
56
16.5999
57
16.5995
67
16.599
40
16.5985
54
16.5981
55
16.5976
66
16.5972
72
16.5967
57
16.5962
54
16.5958
59
16.5953
58
16.5948
61
16.5944
67
16.5939
62
16.5934
53
16.593
55
16.5925
61
16.592
55
16.5916
61
16.5911
47
16.5907
46
16.5902
52
16.5897
49
16.5893
56
16.5888
49
16.5883
54
16.5879
48
16.5874
62
16.5869
54
16.5865
41
16.586
48
16.5855
42
16.5851
64
16.5846
60
16.5842
56
16.5837
58
16.5832
60
16.5828
50
16.5823
56
16.5818
52
16.5814
58
16.5809
C 1s 14
09092210.pro:Sample_Pro_Sb_NativeOxide
122
9
9
0
0
0
0
8
Casa Info Follows
0
0
0
0
JRG_KN_SbatCu_addstudies_DW_cPANpol
( 0 m , 0 m , 0 m ) Angle: 45 degrees , 0 degrees
SputterRaster: 10.0 0.0 um
XPS
3600
PHI1486
1486.6
350
1e+037
1e+037
1e+037
1e+037
FAT
23.5
1e+037
4.5
1e+037
1e+037
1e+037
1e+037
1e+037
C
1s
-1
Kinetic Energy
eV
1192.6
0.1
2
Intensity
d
Transmission
d
pulse counting
0.1
1
1e+037
1e+037
1e+037
1e+037
2
ESCAPE DEPTH TYPE
d
0
PHI_AtomicNumber
d
6
280
0
1
0
1
36
16.6457
46
16.6452
34
16.6447
39
16.6443
52
16.6438
47
16.6433
51
16.6429
51
16.6424
59
16.6419
54
16.6415
54
16.641
71
16.6405
36
16.6401
61
16.6396
66
16.6391
56
16.6387
55
16.6382
59
16.6377
50
16.6373
52
16.6368
43
16.6363
60
16.6359
54
16.6354
47
16.6349
46
16.6345
53
16.634
58
16.6335
69
16.633
63
16.6326
68
16.6321
53
16.6316
60
16.6312
58
16.6307
55
16.6302
78
16.6298
47
16.6293
60
16.6288
51
16.6284
60
16.6279
44
16.6274
54
16.627
64
16.6265
64
16.626
56
16.6256
54
16.6251
46
16.6246
57
16.6242
57
16.6237
63
16.6232
69
16.6228
44
16.6223
61
16.6218
61
16.6214
56
16.6209
61
16.6204
64
16.62
62
16.6195
64
16.619
78
16.6186
52
16.6181
70
16.6176
61
16.6172
58
16.6167
63
16.6162
57
16.6158
60
16.6153
55
16.6148
60
16.6144
48
16.6139
72
16.6134
52
16.613
68
16.6125
54
16.612
40
16.6116
65
16.6111
48
16.6106
50
16.6102
54
16.6097
46
16.6092
63
16.6088
58
16.6083
56
16.6079
62
16.6074
55
16.6069
50
16.6065
63
16.606
43
16.6055
61
16.6051
57
16.6046
46
16.6041
60
16.6037
56
16.6032
66
16.6027
61
16.6023
52
16.6018
63
16.6013
54
16.6009
48
16.6004
63
16.5999
41
16.5995
58
16.599
57
16.5985
54
16.5981
59
16.5976
59
16.5972
55
16.5967
63
16.5962
56
16.5958
47
16.5953
60
16.5948
54
16.5944
53
16.5939
44
16.5934
52
16.593
52
16.5925
50
16.592
59
16.5916
42
16.5911
50
16.5907
47
16.5902
59
16.5897
53
16.5893
61
16.5888
52
16.5883
53
16.5879
51
16.5874
57
16.5869
60
16.5865
49
16.586
51
16.5855
51
16.5851
50
16.5846
49
16.5842
60
16.5837
52
16.5832
61
16.5828
57
16.5823
53
16.5818
79
16.5814
54
16.5809
C 1s 15
09092210.pro:Sample_Pro_Sb_NativeOxide
122
9
9
0
0
0
0
8
Casa Info Follows
0
0
0
0
JRG_KN_SbatCu_addstudies_DW_cPANpol
( 0 m , 0 m , 0 m ) Angle: 45 degrees , 0 degrees
SputterRaster: 10.0 0.0 um
XPS
3900
PHI1486
1486.6
350
1e+037
1e+037
1e+037
1e+037
FAT
23.5
1e+037
4.5
1e+037
1e+037
1e+037
1e+037
1e+037
C
1s
-1
Kinetic Energy
eV
1192.6
0.1
2
Intensity
d
Transmission
d
pulse counting
0.1
1
1e+037
1e+037
1e+037
1e+037
2
ESCAPE DEPTH TYPE
d
0
PHI_AtomicNumber
d
6
280
0
1
0
1
31
16.6457
41
16.6452
43
16.6447
52
16.6443
46
16.6438
48
16.6433
52
16.6429
50
16.6424
48
16.6419
60
16.6415
49
16.641
44
16.6405
51
16.6401
45
16.6396
49
16.6391
56
16.6387
54
16.6382
45
16.6377
42
16.6373
59
16.6368
74
16.6363
47
16.6359
64
16.6354
57
16.6349
49
16.6345
48
16.634
45
16.6335
56
16.633
49
16.6326
65
16.6321
65
16.6316
54
16.6312
56
16.6307
51
16.6302
49
16.6298
53
16.6293
60
16.6288
51
16.6284
59
16.6279
49
16.6274
59
16.627
56
16.6265
65
16.626
56
16.6256
59
16.6251
57
16.6246
48
16.6242
43
16.6237
51
16.6232
44
16.6228
58
16.6223
61
16.6218
56
16.6214
62
16.6209
58
16.6204
47
16.62
54
16.6195
52
16.619
57
16.6186
63
16.6181
54
16.6176
45
16.6172
56
16.6167
52
16.6162
60
16.6158
57
16.6153
65
16.6148
44
16.6144
58
16.6139
47
16.6134
55
16.613
46
16.6125
44
16.612
45
16.6116
53
16.6111
42
16.6106
61
16.6102
60
16.6097
57
16.6092
58
16.6088
48
16.6083
62
16.6079
45
16.6074
52
16.6069
42
16.6065
52
16.606
54
16.6055
52
16.6051
41
16.6046
39
16.6041
52
16.6037
56
16.6032
55
16.6027
60
16.6023
54
16.6018
59
16.6013
55
16.6009
55
16.6004
62
16.5999
64
16.5995
47
16.599
52
16.5985
68
16.5981
51
16.5976
55
16.5972
75
16.5967
59
16.5962
59
16.5958
53
16.5953
53
16.5948
40
16.5944
49
16.5939
66
16.5934
59
16.593
51
16.5925
67
16.592
49
16.5916
51
16.5911
53
16.5907
49
16.5902
61
16.5897
36
16.5893
56
16.5888
51
16.5883
61
16.5879
62
16.5874
56
16.5869
49
16.5865
53
16.586
57
16.5855
54
16.5851
55
16.5846
68
16.5842
59
16.5837
57
16.5832
57
16.5828
52
16.5823
67
16.5818
53
16.5814
58
16.5809
C 1s 16
09092210.pro:Sample_Pro_Sb_NativeOxide
122
9
9
0
0
0
0
8
Casa Info Follows
0
0
0
0
JRG_KN_SbatCu_addstudies_DW_cPANpol
( 0 m , 0 m , 0 m ) Angle: 45 degrees , 0 degrees
SputterRaster: 10.0 0.0 um
XPS
4200
PHI1486
1486.6
350
1e+037
1e+037
1e+037
1e+037
FAT
23.5
1e+037
4.5
1e+037
1e+037
1e+037
1e+037
1e+037
C
1s
-1
Kinetic Energy
eV
1192.6
0.1
2
Intensity
d
Transmission
d
pulse counting
0.1
1
1e+037
1e+037
1e+037
1e+037
2
ESCAPE DEPTH TYPE
d
0
PHI_AtomicNumber
d
6
280
0
1
0
1
30
16.6457
43
16.6452
31
16.6447
46
16.6443
37
16.6438
48
16.6433
49
16.6429
49
16.6424
55
16.6419
54
16.6415
57
16.641
44
16.6405
39
16.6401
58
16.6396
48
16.6391
46
16.6387
55
16.6382
50
16.6377
60
16.6373
69
16.6368
50
16.6363
57
16.6359
49
16.6354
52
16.6349
65
16.6345
51
16.634
56
16.6335
49
16.633
43
16.6326
63
16.6321
39
16.6316
50
16.6312
67
16.6307
48
16.6302
65
16.6298
57
16.6293
64
16.6288
54
16.6284
62
16.6279
56
16.6274
68
16.627
57
16.6265
54
16.626
45
16.6256
61
16.6251
43
16.6246
63
16.6242
59
16.6237
52
16.6232
57
16.6228
46
16.6223
51
16.6218
44
16.6214
64
16.6209
58
16.6204
59
16.62
58
16.6195
59
16.619
47
16.6186
54
16.6181
59
16.6176
54
16.6172
51
16.6167
53
16.6162
61
16.6158
56
16.6153
48
16.6148
48
16.6144
48
16.6139
49
16.6134
42
16.613
50
16.6125
55
16.612
53
16.6116
42
16.6111
52
16.6106
62
16.6102
47
16.6097
51
16.6092
58
16.6088
53
16.6083
54
16.6079
47
16.6074
59
16.6069
56
16.6065
55
16.606
64
16.6055
66
16.6051
57
16.6046
51
16.6041
47
16.6037
50
16.6032
63
16.6027
40
16.6023
61
16.6018
46
16.6013
67
16.6009
61
16.6004
50
16.5999
55
16.5995
63
16.599
53
16.5985
51
16.5981
45
16.5976
66
16.5972
71
16.5967
56
16.5962
56
16.5958
55
16.5953
46
16.5948
47
16.5944
44
16.5939
46
16.5934
57
16.593
50
16.5925
55
16.592
63
16.5916
56
16.5911
62
16.5907
57
16.5902
57
16.5897
66
16.5893
64
16.5888
55
16.5883
58
16.5879
64
16.5874
61
16.5869
52
16.5865
49
16.586
64
16.5855
58
16.5851
52
16.5846
51
16.5842
49
16.5837
38
16.5832
57
16.5828
50
16.5823
57
16.5818
63
16.5814
54
16.5809
C 1s 17
09092210.pro:Sample_Pro_Sb_NativeOxide
122
9
9
0
0
0
0
8
Casa Info Follows
0
0
0
0
JRG_KN_SbatCu_addstudies_DW_cPANpol
( 0 m , 0 m , 0 m ) Angle: 45 degrees , 0 degrees
SputterRaster: 10.0 0.0 um
XPS
4500
PHI1486
1486.6
350
1e+037
1e+037
1e+037
1e+037
FAT
23.5
1e+037
4.5
1e+037
1e+037
1e+037
1e+037
1e+037
C
1s
-1
Kinetic Energy
eV
1192.6
0.1
2
Intensity
d
Transmission
d
pulse counting
0.1
1
1e+037
1e+037
1e+037
1e+037
2
ESCAPE DEPTH TYPE
d
0
PHI_AtomicNumber
d
6
280
0
1
0
1
35
16.6457
28
16.6452
43
16.6447
37
16.6443
40
16.6438
52
16.6433
49
16.6429
54
16.6424
48
16.6419
53
16.6415
55
16.641
52
16.6405
58
16.6401
46
16.6396
52
16.6391
52
16.6387
61
16.6382
57
16.6377
51
16.6373
54
16.6368
57
16.6363
59
16.6359
54
16.6354
63
16.6349
57
16.6345
63
16.634
48
16.6335
51
16.633
42
16.6326
49
16.6321
38
16.6316
53
16.6312
62
16.6307
60
16.6302
44
16.6298
50
16.6293
60
16.6288
57
16.6284
46
16.6279
49
16.6274
61
16.627
70
16.6265
49
16.626
48
16.6256
63
16.6251
58
16.6246
60
16.6242
56
16.6237
55
16.6232
53
16.6228
56
16.6223
55
16.6218
58
16.6214
58
16.6209
52
16.6204
62
16.62
59
16.6195
48
16.619
54
16.6186
60
16.6181
47
16.6176
66
16.6172
52
16.6167
58
16.6162
70
16.6158
54
16.6153
72
16.6148
48
16.6144
48
16.6139
44
16.6134
55
16.613
55
16.6125
67
16.612
50
16.6116
41
16.6111
57
16.6106
49
16.6102
53
16.6097
73
16.6092
56
16.6088
61
16.6083
42
16.6079
56
16.6074
70
16.6069
55
16.6065
61
16.606
54
16.6055
53
16.6051
60
16.6046
58
16.6041
44
16.6037
51
16.6032
47
16.6027
58
16.6023
62
16.6018
57
16.6013
62
16.6009
67
16.6004
50
16.5999
61
16.5995
54
16.599
64
16.5985
53
16.5981
54
16.5976
53
16.5972
49
16.5967
49
16.5962
66
16.5958
46
16.5953
57
16.5948
58
16.5944
54
16.5939
59
16.5934
48
16.593
45
16.5925
50
16.592
56
16.5916
59
16.5911
53
16.5907
52
16.5902
59
16.5897
47
16.5893
60
16.5888
43
16.5883
67
16.5879
65
16.5874
43
16.5869
69
16.5865
59
16.586
65
16.5855
59
16.5851
54
16.5846
50
16.5842
54
16.5837
64
16.5832
64
16.5828
56
16.5823
60
16.5818
57
16.5814
55
16.5809
Sb 3d 18
09092210.pro:Sample_Pro_Sb_NativeOxide
122
9
9
0
0
0
0
16
Casa Info Follows
1
Calib M = 285.0708 A = 285 BE ADD
0
2
CASA region (*Sb 3d*) (*Shirley*) 951.36253 961.08052 23.951267 2 0 0 0 -450 0 0 (*Sb 3d*) 121.759 0 27.7
CASA region (*Sb 3d*) (*Shirley*) 942.6426 951.86156 23.951267 2 0 0 0 -450 0 0 (*Sb 3d*) 121.759 0 27.7
5
CASA comp (*Sb 3d*) (*GL(70)*) Area 6146.4818 1e-020 247151.73 -1 1 MFWHM 0.98147026 0.3 7.5 -1 1 Position 958.37687 951.36253 960.9492 -1 1 RSF 23.951267 MASS 121.759 INDEX -1 (*Sb 3d*) CONST (**) UNCORRECTEDRSF 27.7
CASA comp (*Sb 3d*) (*GL(70)*) Area 4097.6566 1e-020 139190.28 0 0.666667 MFWHM 0.98147026 0.3 7.5 0 1 Position 949.03687 0 0 0 -9.34 RSF 23.951267 MASS 121.759 INDEX -1 (*Sb 3d*) CONST (**) UNCORRECTEDRSF 27.7
CASA comp (*Sb 3d*) (*GL(30)*) Area 20664.641 1e-020 247151.73 -1 1 MFWHM 1.3762736 0.3 7.5 -1 1 Position 956.00833 951.36253 960.9492 -1 1 RSF 23.951267 MASS 121.759 INDEX -1 (*SbO 3d*) CONST (**) UNCORRECTEDRSF 27.7
CASA comp (*Sb 3d*) (*GL(30)*) Area 13776.434 1e-020 139190.28 2 0.666667 MFWHM 1.3762736 0.3 7.5 2 1 Position 946.66833 0 0 2 -9.34 RSF 23.951267 MASS 121.759 INDEX -1 (*SbO 3d*) CONST (**) UNCORRECTEDRSF 27.7
CASA comp (*O 1s*) (*GL(0)*) Area 5711.085 1e-020 61626.59 -1 1 MFWHM 2.5937799 0.4317667 10.794168 -1 1 Position 955.52543 951.36253 960.9492 -1 1 RSF 0.733 MASS 15.9994 INDEX -1 (*O 1s*) CONST (**) UNCORRECTEDRSF 0.733
JRG_KN_SbatCu_addstudies_DW_cPANpol
( 0 m , 0 m , 0 m ) Angle: 45 degrees , 0 degrees
SputterRaster: 10.0 0.0 um
XPS
-10
PHI1486
1486.6
350
1e+037
1e+037
1e+037
1e+037
FAT
23.5
1e+037
4.5
1e+037
1e+037
1e+037
1e+037
1e+037
Sb
3d
-1
Kinetic Energy
eV
941.6
0.1
2
Intensity
d
Transmission
d
pulse counting
0.1
1
1e+037
1e+037
1e+037
1e+037
4
ESCAPE DEPTH TYPE
d
0
PHI_AtomicNumber
d
51
PROPAGATION_CONVERGED
d
1
MFP Exponent
d
0
400
0
1
0
1
287
17.9502
288
17.9496
285
17.949
263
17.9484
305
17.9479
315
17.9473
306
17.9467
256
17.9461
272
17.9456
256
17.945
264
17.9444
271
17.9438
255
17.9433
282
17.9427
279
17.9421
268
17.9416
275
17.941
254
[...]
75
16.0924
63
16.0919
84
16.0915
70
16.0911
88
16.0907
75
16.0902
73
16.0898
84
16.0894
75
16.089
76
16.0885
73
16.0881
67
16.0877
71
16.0873
73
16.0868
85
16.0864
57
16.086
79
16.0856
62
16.0851
76
16.0847
90
16.0843
71
16.0839
70
16.0834
64
16.083
72
16.0826
65
16.0822
77
16.0817
65
16.0813
72
16.0809
60
16.0805
72
16.08
97
16.0796
83
16.0792
71
16.0788
87
16.0784
82
16.0779
90
16.0775
70
16.0771
89
16.0767
61
16.0762
70
16.0758
83
16.0754
78
16.075
72
16.0745
76
16.0741
84
16.0737
63
16.0733
72
16.0728
61
16.0724
75
16.072
68
16.0716
83
16.0712
77
16.0707
73
16.0703
71
16.0699
73
16.0695
76
16.069
80
16.0686
81
16.0682
81
16.0678
70
16.0673
69
16.0669
69
16.0665
75
16.0661
98
16.0657
61
16.0652
74
16.0648
98
16.0644
72
16.064
75
16.0635
82
16.0631
65
16.0627
79
16.0623
66
16.0619
58
16.0614
64
16.061
66
16.0606
71
16.0602
67
16.0597
78
16.0593
74
16.0589
94
16.0585
74
16.0581
99
16.0576
76
16.0572
84
16.0568
73
16.0564
85
16.0559
80
16.0555
68
16.0551
73
16.0547
73
16.0543
74
16.0538
87
16.0534
79
16.053
62
16.0526
69
16.0521
74
16.0517
81
16.0513
69
16.0509
71
16.0505
54
16.05
77
16.0496
63
16.0492
74
16.0488
76
16.0484
75
16.0479
69
16.0475
54
16.0471
72
16.0467
67
16.0462
82
16.0458
79
16.0454
87
16.045
78
16.0446
83
16.0441
79
16.0437
78
16.0433
78
16.0429
87
16.0425
73
16.042
S 2p3/2 62
09092210.pro:Sample_Pro_Sb_NativeOxide
122
9
9
0
0
0
0
8
Casa Info Follows
0
0
0
0
JRG_KN_SbatCu_addstudies_DW_cPANpol
( 0 m , 0 m , 0 m ) Angle: 45 degrees , 0 degrees
SputterRaster: 10.0 0.0 um
XPS
2700
PHI1486
1486.6
350
1e+037
1e+037
1e+037
1e+037
FAT
23.5
1e+037
4.5
1e+037
1e+037
1e+037
1e+037
1e+037
S
2p3/2
-1
Kinetic Energy
eV
1308.6
0.1
2
Intensity
d
Transmission
d
pulse counting
0.1
1
1e+037
1e+037
1e+037
1e+037
2
ESCAPE DEPTH TYPE
d
0
PHI_AtomicNumber
d
16
400
0
1
0
1
70
16.1264
64
16.126
58
16.1256
72
16.1252
72
16.1247
71
16.1243
77
16.1239
66
16.1235
69
16.123
60
16.1226
68
16.1222
61
16.1217
59
16.1213
74
16.1209
81
16.1205
65
16.12
72
16.1196
57
16.1192
80
16.1188
67
16.1183
73
16.1179
83
16.1175
83
16.117
74
16.1166
64
16.1162
83
16.1158
79
16.1153
73
16.1149
70
16.1145
64
16.1141
77
16.1136
70
16.1132
58
16.1128
85
16.1124
59
16.1119
72
16.1115
65
16.1111
83
16.1107
84
16.1102
77
16.1098
69
16.1094
70
16.1089
72
16.1085
68
16.1081
63
16.1077
90
16.1072
64
16.1068
63
16.1064
52
16.106
78
16.1055
72
16.1051
68
16.1047
70
16.1043
82
16.1038
76
16.1034
74
16.103
78
16.1026
85
16.1021
69
16.1017
58
16.1013
68
16.1009
91
16.1004
77
16.1
89
16.0996
81
16.0992
66
16.0987
75
16.0983
74
16.0979
65
16.0975
77
16.097
75
16.0966
75
16.0962
85
16.0958
78
16.0953
67
16.0949
77
16.0945
66
16.0941
73
16.0936
72
16.0932
82
16.0928
82
16.0924
91
16.0919
79
16.0915
64
16.0911
79
16.0907
73
16.0902
69
16.0898
78
16.0894
64
16.089
87
16.0885
71
16.0881
58
16.0877
73
16.0873
68
16.0868
66
16.0864
77
16.086
70
16.0856
88
16.0851
66
16.0847
78
16.0843
72
16.0839
70
16.0834
67
16.083
77
16.0826
76
16.0822
63
16.0817
65
16.0813
76
16.0809
65
16.0805
63
16.08
75
16.0796
76
16.0792
71
16.0788
76
16.0784
74
16.0779
62
16.0775
63
16.0771
69
16.0767
58
16.0762
69
16.0758
67
16.0754
83
16.075
75
16.0745
79
16.0741
70
16.0737
71
16.0733
82
16.0728
71
16.0724
98
16.072
84
16.0716
72
16.0712
85
16.0707
68
16.0703
75
16.0699
75
16.0695
67
16.069
91
16.0686
78
16.0682
76
16.0678
86
16.0673
82
16.0669
81
16.0665
75
16.0661
76
16.0657
72
16.0652
71
16.0648
60
16.0644
58
16.064
63
16.0635
68
16.0631
81
16.0627
71
16.0623
70
16.0619
79
16.0614
89
16.061
62
16.0606
74
16.0602
70
16.0597
79
16.0593
64
16.0589
81
16.0585
84
16.0581
84
16.0576
76
16.0572
83
16.0568
74
16.0564
70
16.0559
83
16.0555
78
16.0551
84
16.0547
75
16.0543
72
16.0538
85
16.0534
63
16.053
60
16.0526
78
16.0521
76
16.0517
77
16.0513
85
16.0509
81
16.0505
75
16.05
64
16.0496
78
16.0492
66
16.0488
90
16.0484
84
16.0479
65
16.0475
84
16.0471
65
16.0467
75
16.0462
86
16.0458
76
16.0454
84
16.045
77
16.0446
63
16.0441
71
16.0437
74
16.0433
84
16.0429
85
16.0425
84
16.042
S 2p3/2 63
09092210.pro:Sample_Pro_Sb_NativeOxide
122
9
9
0
0
0
0
8
Casa Info Follows
0
0
0
0
JRG_KN_SbatCu_addstudies_DW_cPANpol
( 0 m , 0 m , 0 m ) Angle: 45 degrees , 0 degrees
SputterRaster: 10.0 0.0 um
XPS
3000
PHI1486
1486.6
350
1e+037
1e+037
1e+037
1e+037
FAT
23.5
1e+037
4.5
1e+037
1e+037
1e+037
1e+037
1e+037
S
2p3/2
-1
Kinetic Energy
eV
1308.6
0.1
2
Intensity
d
Transmission
d
pulse counting
0.1
1
1e+037
1e+037
1e+037
1e+037
2
ESCAPE DEPTH TYPE
d
0
PHI_AtomicNumber
d
16
400
0
1
0
1
65
16.1264
64
16.126
60
16.1256
62
16.1252
63
16.1247
56
16.1243
76
16.1239
63
16.1235
62
16.123
58
16.1226
75
16.1222
64
16.1217
69
16.1213
71
16.1209
69
16.1205
73
16.12
67
16.1196
66
16.1192
73
16.1188
79
16.1183
80
16.1179
81
16.1175
77
16.117
73
16.1166
71
16.1162
62
16.1158
63
16.1153
70
16.1149
75
16.1145
67
16.1141
73
16.1136
68
16.1132
73
16.1128
75
16.1124
77
16.1119
69
16.1115
64
16.1111
71
16.1107
67
16.1102
69
16.1098
62
16.1094
89
16.1089
67
16.1085
79
16.1081
68
16.1077
69
16.1072
78
16.1068
89
16.1064
90
16.106
65
16.1055
67
16.1051
66
16.1047
72
16.1043
61
16.1038
62
16.1034
69
16.103
72
16.1026
73
16.1021
87
16.1017
65
16.1013
72
16.1009
69
16.1004
88
16.1
76
16.0996
70
16.0992
73
16.0987
74
16.0983
90
16.0979
69
16.0975
87
16.097
62
16.0966
71
16.0962
68
16.0958
74
16.0953
86
16.0949
86
16.0945
69
16.0941
68
16.0936
68
16.0932
66
16.0928
74
16.0924
79
16.0919
68
16.0915
75
16.0911
75
16.0907
71
16.0902
76
16.0898
69
16.0894
79
16.089
69
16.0885
81
16.0881
80
16.0877
84
16.0873
84
16.0868
88
16.0864
75
16.086
83
16.0856
79
16.0851
71
16.0847
74
16.0843
82
16.0839
71
16.0834
88
16.083
78
16.0826
63
16.0822
79
16.0817
56
16.0813
85
16.0809
66
16.0805
75
16.08
71
16.0796
64
16.0792
86
16.0788
73
16.0784
63
16.0779
78
16.0775
74
16.0771
65
16.0767
70
16.0762
71
16.0758
76
16.0754
86
16.075
77
16.0745
84
16.0741
67
16.0737
70
16.0733
60
16.0728
60
16.0724
72
16.072
80
16.0716
71
16.0712
64
16.0707
71
16.0703
64
16.0699
61
16.0695
57
16.069
64
16.0686
86
16.0682
72
16.0678
63
16.0673
78
16.0669
74
16.0665
76
16.0661
63
16.0657
76
16.0652
81
16.0648
74
16.0644
71
16.064
66
16.0635
61
16.0631
72
16.0627
61
16.0623
74
16.0619
91
16.0614
72
16.061
72
16.0606
77
16.0602
74
16.0597
65
16.0593
56
16.0589
78
16.0585
58
16.0581
88
16.0576
62
16.0572
87
16.0568
61
16.0564
70
16.0559
78
16.0555
79
16.0551
79
16.0547
74
16.0543
74
16.0538
84
16.0534
85
16.053
73
16.0526
79
16.0521
65
16.0517
76
16.0513
69
16.0509
61
16.0505
69
16.05
72
16.0496
53
16.0492
77
16.0488
72
16.0484
69
16.0479
85
16.0475
73
16.0471
71
16.0467
77
16.0462
83
16.0458
72
16.0454
94
16.045
91
16.0446
67
16.0441
72
16.0437
57
16.0433
70
16.0429
63
16.0425
76
16.042
S 2p3/2 64
09092210.pro:Sample_Pro_Sb_NativeOxide
122
9
9
0
0
0
0
8
Casa Info Follows
0
0
0
0
JRG_KN_SbatCu_addstudies_DW_cPANpol
( 0 m , 0 m , 0 m ) Angle: 45 degrees , 0 degrees
SputterRaster: 10.0 0.0 um
XPS
3300
PHI1486
1486.6
350
1e+037
1e+037
1e+037
1e+037
FAT
23.5
1e+037
4.5
1e+037
1e+037
1e+037
1e+037
1e+037
S
2p3/2
-1
Kinetic Energy
eV
1308.6
0.1
2
Intensity
d
Transmission
d
pulse counting
0.1
1
1e+037
1e+037
1e+037
1e+037
2
ESCAPE DEPTH TYPE
d
0
PHI_AtomicNumber
d
16
400
0
1
0
1
65
16.1264
69
16.126
53
16.1256
67
16.1252
68
16.1247
77
16.1243
80
16.1239
80
16.1235
83
16.123
74
16.1226
53
16.1222
71
16.1217
82
16.1213
73
16.1209
70
16.1205
74
16.12
69
16.1196
76
16.1192
70
16.1188
61
16.1183
59
16.1179
62
16.1175
89
16.117
72
16.1166
65
16.1162
63
16.1158
77
16.1153
70
16.1149
65
16.1145
62
16.1141
71
16.1136
78
16.1132
59
16.1128
81
16.1124
69
16.1119
81
16.1115
95
16.1111
83
16.1107
70
16.1102
62
16.1098
76
16.1094
66
16.1089
86
16.1085
82
16.1081
73
16.1077
79
16.1072
50
16.1068
76
16.1064
70
16.106
75
16.1055
80
16.1051
73
16.1047
74
16.1043
81
16.1038
63
16.1034
61
16.103
66
16.1026
72
16.1021
78
16.1017
65
16.1013
96
16.1009
63
16.1004
74
16.1
65
16.0996
75
16.0992
76
16.0987
64
16.0983
80
16.0979
69
16.0975
73
16.097
77
16.0966
73
16.0962
65
16.0958
68
16.0953
74
16.0949
67
16.0945
84
16.0941
72
16.0936
59
16.0932
81
16.0928
74
16.0924
70
16.0919
76
16.0915
93
16.0911
82
16.0907
70
16.0902
70
16.0898
83
16.0894
86
16.089
83
16.0885
85
16.0881
79
16.0877
71
16.0873
69
16.0868
74
16.0864
69
16.086
61
16.0856
87
16.0851
56
16.0847
76
16.0843
85
16.0839
72
16.0834
74
16.083
83
16.0826
71
16.0822
62
16.0817
61
16.0813
72
16.0809
62
16.0805
79
16.08
66
16.0796
94
16.0792
73
16.0788
87
16.0784
68
16.0779
75
16.0775
64
16.0771
75
16.0767
75
16.0762
73
16.0758
70
16.0754
72
16.075
87
16.0745
57
16.0741
91
16.0737
68
16.0733
81
16.0728
63
16.0724
72
16.072
79
16.0716
71
16.0712
86
16.0707
70
16.0703
82
16.0699
88
16.0695
85
16.069
63
16.0686
69
16.0682
85
16.0678
68
16.0673
80
16.0669
62
16.0665
72
16.0661
62
16.0657
76
16.0652
74
16.0648
77
16.0644
62
16.064
77
16.0635
80
16.0631
77
16.0627
62
16.0623
75
16.0619
74
16.0614
94
16.061
66
16.0606
75
16.0602
79
16.0597
72
16.0593
62
16.0589
70
16.0585
77
16.0581
82
16.0576
71
16.0572
72
16.0568
70
16.0564
82
16.0559
85
16.0555
79
16.0551
73
16.0547
74
16.0543
78
16.0538
70
16.0534
90
16.053
69
16.0526
67
16.0521
72
16.0517
69
16.0513
79
16.0509
77
16.0505
70
16.05
73
16.0496
67
16.0492
65
16.0488
73
16.0484
81
16.0479
59
16.0475
69
16.0471
59
16.0467
73
16.0462
68
16.0458
84
16.0454
84
16.045
74
16.0446
89
16.0441
67
16.0437
86
16.0433
47
16.0429
73
16.0425
65
16.042
S 2p3/2 65
09092210.pro:Sample_Pro_Sb_NativeOxide
122
9
9
0
0
0
0
8
Casa Info Follows
0
0
0
0
JRG_KN_SbatCu_addstudies_DW_cPANpol
( 0 m , 0 m , 0 m ) Angle: 45 degrees , 0 degrees
SputterRaster: 10.0 0.0 um
XPS
3600
PHI1486
1486.6
350
1e+037
1e+037
1e+037
1e+037
FAT
23.5
1e+037
4.5
1e+037
1e+037
1e+037
1e+037
1e+037
S
2p3/2
-1
Kinetic Energy
eV
1308.6
0.1
2
Intensity
d
Transmission
d
pulse counting
0.1
1
1e+037
1e+037
1e+037
1e+037
2
ESCAPE DEPTH TYPE
d
0
PHI_AtomicNumber
d
16
400
0
1
0
1
58
16.1264
69
16.126
63
16.1256
75
16.1252
78
16.1247
85
16.1243
67
16.1239
67
16.1235
87
16.123
67
16.1226
66
16.1222
78
16.1217
67
16.1213
72
16.1209
72
16.1205
76
16.12
66
16.1196
59
16.1192
67
16.1188
59
16.1183
78
16.1179
64
16.1175
70
16.117
71
16.1166
64
16.1162
61
16.1158
60
16.1153
72
16.1149
63
16.1145
78
16.1141
67
16.1136
67
16.1132
71
16.1128
60
16.1124
69
16.1119
62
16.1115
58
16.1111
62
16.1107
72
16.1102
69
16.1098
70
16.1094
70
16.1089
68
16.1085
79
16.1081
73
16.1077
65
16.1072
78
16.1068
65
16.1064
72
16.106
64
16.1055
61
16.1051
61
16.1047
62
16.1043
64
16.1038
82
16.1034
78
16.103
70
16.1026
74
16.1021
78
16.1017
78
16.1013
60
16.1009
76
16.1004
81
16.1
70
16.0996
67
16.0992
64
16.0987
67
16.0983
57
16.0979
83
16.0975
70
16.097
79
16.0966
52
16.0962
65
16.0958
63
16.0953
80
16.0949
74
16.0945
89
16.0941
76
16.0936
77
16.0932
74
16.0928
77
16.0924
75
16.0919
70
16.0915
82
16.0911
66
16.0907
74
16.0902
71
16.0898
71
16.0894
64
16.089
71
16.0885
77
16.0881
70
16.0877
68
16.0873
68
16.0868
70
16.0864
70
16.086
95
16.0856
62
16.0851
63
16.0847
83
16.0843
68
16.0839
66
16.0834
63
16.083
79
16.0826
69
16.0822
74
16.0817
78
16.0813
79
16.0809
85
16.0805
69
16.08
72
16.0796
87
16.0792
68
16.0788
69
16.0784
61
16.0779
82
16.0775
67
16.0771
70
16.0767
83
16.0762
74
16.0758
69
16.0754
64
16.075
63
16.0745
54
16.0741
71
16.0737
64
16.0733
93
16.0728
72
16.0724
87
16.072
57
16.0716
83
16.0712
75
16.0707
58
16.0703
68
16.0699
72
16.0695
53
16.069
81
16.0686
61
16.0682
68
16.0678
71
16.0673
61
16.0669
60
16.0665
70
16.0661
80
16.0657
71
16.0652
76
16.0648
82
16.0644
71
16.064
78
16.0635
82
16.0631
84
16.0627
68
16.0623
71
16.0619
71
16.0614
78
16.061
81
16.0606
75
16.0602
72
16.0597
79
16.0593
86
16.0589
87
16.0585
74
16.0581
90
16.0576
61
16.0572
81
16.0568
91
16.0564
66
16.0559
91
16.0555
90
16.0551
85
16.0547
77
16.0543
84
16.0538
68
16.0534
66
16.053
64
16.0526
67
16.0521
53
16.0517
76
16.0513
66
16.0509
66
16.0505
79
16.05
82
16.0496
56
16.0492
78
16.0488
69
16.0484
75
16.0479
71
16.0475
75
16.0471
72
16.0467
67
16.0462
71
16.0458
65
16.0454
69
16.045
77
16.0446
71
16.0441
70
16.0437
70
16.0433
76
16.0429
66
16.0425
72
16.042
S 2p3/2 66
09092210.pro:Sample_Pro_Sb_NativeOxide
122
9
9
0
0
0
0
8
Casa Info Follows
0
0
0
0
JRG_KN_SbatCu_addstudies_DW_cPANpol
( 0 m , 0 m , 0 m ) Angle: 45 degrees , 0 degrees
SputterRaster: 10.0 0.0 um
XPS
3900
PHI1486
1486.6
350
1e+037
1e+037
1e+037
1e+037
FAT
23.5
1e+037
4.5
1e+037
1e+037
1e+037
1e+037
1e+037
S
2p3/2
-1
Kinetic Energy
eV
1308.6
0.1
2
Intensity
d
Transmission
d
pulse counting
0.1
1
1e+037
1e+037
1e+037
1e+037
2
ESCAPE DEPTH TYPE
d
0
PHI_AtomicNumber
d
16
400
0
1
0
1
62
16.1264
70
16.126
61
16.1256
55
16.1252
49
16.1247
66
16.1243
65
16.1239
65
16.1235
73
16.123
77
16.1226
67
16.1222
73
16.1217
60
16.1213
74
16.1209
59
16.1205
74
16.12
75
16.1196
72
16.1192
64
16.1188
73
16.1183
79
16.1179
69
16.1175
70
16.117
75
16.1166
71
16.1162
70
16.1158
52
16.1153
76
16.1149
59
16.1145
71
16.1141
62
16.1136
82
16.1132
75
16.1128
72
16.1124
84
16.1119
71
16.1115
87
16.1111
63
16.1107
73
16.1102
75
16.1098
63
16.1094
79
16.1089
52
16.1085
67
16.1081
68
16.1077
70
16.1072
69
16.1068
84
16.1064
59
16.106
64
16.1055
59
16.1051
84
16.1047
74
16.1043
73
16.1038
70
16.1034
84
16.103
83
16.1026
68
16.1021
81
16.1017
66
16.1013
78
16.1009
68
16.1004
64
16.1
62
16.0996
80
16.0992
73
16.0987
67
16.0983
71
16.0979
78
16.0975
66
16.097
79
16.0966
87
16.0962
77
16.0958
85
16.0953
78
16.0949
72
16.0945
70
16.0941
74
16.0936
70
16.0932
78
16.0928
67
16.0924
70
16.0919
72
16.0915
59
16.0911
68
16.0907
59
16.0902
71
16.0898
78
16.0894
74
16.089
65
16.0885
77
16.0881
71
16.0877
81
16.0873
66
16.0868
83
16.0864
75
16.086
79
16.0856
66
16.0851
87
16.0847
82
16.0843
73
16.0839
92
16.0834
86
16.083
62
16.0826
65
16.0822
74
16.0817
65
16.0813
63
16.0809
70
16.0805
63
16.08
63
16.0796
73
16.0792
56
16.0788
65
16.0784
60
16.0779
63
16.0775
75
16.0771
67
16.0767
75
16.0762
71
16.0758
68
16.0754
65
16.075
64
16.0745
74
16.0741
70
16.0737
68
16.0733
76
16.0728
66
16.0724
72
16.072
64
16.0716
62
16.0712
71
16.0707
82
16.0703
74
16.0699
66
16.0695
66
16.069
75
16.0686
65
16.0682
67
16.0678
85
16.0673
71
16.0669
72
16.0665
65
16.0661
85
16.0657
63
16.0652
66
16.0648
81
16.0644
63
16.064
67
16.0635
78
16.0631
71
16.0627
68
16.0623
82
16.0619
76
16.0614
69
16.061
65
16.0606
68
16.0602
78
16.0597
72
16.0593
64
16.0589
80
16.0585
82
16.0581
83
16.0576
80
16.0572
84
16.0568
83
16.0564
88
16.0559
68
16.0555
75
16.0551
63
16.0547
79
16.0543
63
16.0538
89
16.0534
73
16.053
76
16.0526
67
16.0521
70
16.0517
57
16.0513
75
16.0509
63
16.0505
83
16.05
72
16.0496
66
16.0492
70
16.0488
71
16.0484
85
16.0479
70
16.0475
82
16.0471
63
16.0467
84
16.0462
68
16.0458
59
16.0454
67
16.045
72
16.0446
58
16.0441
78
16.0437
66
16.0433
82
16.0429
60
16.0425
72
16.042
S 2p3/2 67
09092210.pro:Sample_Pro_Sb_NativeOxide
122
9
9
0
0
0
0
8
Casa Info Follows
0
0
0
0
JRG_KN_SbatCu_addstudies_DW_cPANpol
( 0 m , 0 m , 0 m ) Angle: 45 degrees , 0 degrees
SputterRaster: 10.0 0.0 um
XPS
4200
PHI1486
1486.6
350
1e+037
1e+037
1e+037
1e+037
FAT
23.5
1e+037
4.5
1e+037
1e+037
1e+037
1e+037
1e+037
S
2p3/2
-1
Kinetic Energy
eV
1308.6
0.1
2
Intensity
d
Transmission
d
pulse counting
0.1
1
1e+037
1e+037
1e+037
1e+037
2
ESCAPE DEPTH TYPE
d
0
PHI_AtomicNumber
d
16
400
0
1
0
1
55
16.1264
60
16.126
65
16.1256
63
16.1252
77
16.1247
73
16.1243
69
16.1239
86
16.1235
59
16.123
70
16.1226
75
16.1222
59
16.1217
55
16.1213
74
16.1209
65
16.1205
58
16.12
64
16.1196
71
16.1192
67
16.1188
54
16.1183
79
16.1179
83
16.1175
69
16.117
64
16.1166
64
16.1162
61
16.1158
68
16.1153
57
16.1149
64
16.1145
62
16.1141
56
16.1136
60
16.1132
68
16.1128
73
16.1124
54
16.1119
54
16.1115
68
16.1111
72
16.1107
59
16.1102
64
16.1098
72
16.1094
76
16.1089
64
16.1085
99
16.1081
76
16.1077
65
16.1072
62
16.1068
65
16.1064
65
16.106
74
16.1055
69
16.1051
73
16.1047
61
16.1043
92
16.1038
82
16.1034
93
16.103
68
16.1026
61
16.1021
76
16.1017
79
16.1013
76
16.1009
84
16.1004
75
16.1
66
16.0996
63
16.0992
67
16.0987
65
16.0983
86
16.0979
68
16.0975
69
16.097
73
16.0966
80
16.0962
74
16.0958
72
16.0953
71
16.0949
62
16.0945
69
16.0941
75
16.0936
60
16.0932
66
16.0928
65
16.0924
72
16.0919
82
16.0915
56
16.0911
75
16.0907
72
16.0902
72
16.0898
66
16.0894
67
16.089
81
16.0885
71
16.0881
79
16.0877
66
16.0873
78
16.0868
72
16.0864
67
16.086
96
16.0856
74
16.0851
79
16.0847
80
16.0843
70
16.0839
76
16.0834
73
16.083
50
16.0826
71
16.0822
57
16.0817
74
16.0813
77
16.0809
84
16.0805
78
16.08
56
16.0796
68
16.0792
79
16.0788
65
16.0784
68
16.0779
82
16.0775
68
16.0771
50
16.0767
75
16.0762
63
16.0758
73
16.0754
64
16.075
83
16.0745
71
16.0741
67
16.0737
84
16.0733
60
16.0728
73
16.0724
58
16.072
68
16.0716
66
16.0712
67
16.0707
78
16.0703
74
16.0699
74
16.0695
75
16.069
80
16.0686
58
16.0682
61
16.0678
58
16.0673
70
16.0669
75
16.0665
75
16.0661
76
16.0657
70
16.0652
71
16.0648
64
16.0644
68
16.064
66
16.0635
65
16.0631
82
16.0627
85
16.0623
82
16.0619
74
16.0614
75
16.061
88
16.0606
57
16.0602
74
16.0597
70
16.0593
63
16.0589
77
16.0585
70
16.0581
66
16.0576
80
16.0572
65
16.0568
68
16.0564
93
16.0559
76
16.0555
82
16.0551
78
16.0547
81
16.0543
73
16.0538
62
16.0534
53
16.053
72
16.0526
75
16.0521
81
16.0517
66
16.0513
80
16.0509
66
16.0505
91
16.05
71
16.0496
89
16.0492
83
16.0488
76
16.0484
66
16.0479
68
16.0475
68
16.0471
67
16.0467
75
16.0462
89
16.0458
75
16.0454
83
16.045
79
16.0446
64
16.0441
75
16.0437
76
16.0433
59
16.0429
66
16.0425
74
16.042
S 2p3/2 68
09092210.pro:Sample_Pro_Sb_NativeOxide
122
9
9
0
0
0
0
8
Casa Info Follows
0
0
0
0
JRG_KN_SbatCu_addstudies_DW_cPANpol
( 0 m , 0 m , 0 m ) Angle: 45 degrees , 0 degrees
SputterRaster: 10.0 0.0 um
XPS
4500
PHI1486
1486.6
350
1e+037
1e+037
1e+037
1e+037
FAT
23.5
1e+037
4.5
1e+037
1e+037
1e+037
1e+037
1e+037
S
2p3/2
-1
Kinetic Energy
eV
1308.6
0.1
2
Intensity
d
Transmission
d
pulse counting
0.1
1
1e+037
1e+037
1e+037
1e+037
2
ESCAPE DEPTH TYPE
d
0
PHI_AtomicNumber
d
16
400
0
1
0
1
61
16.1264
82
16.126
63
16.1256
81
16.1252
67
16.1247
67
16.1243
63
16.1239
69
16.1235
65
16.123
76
16.1226
72
16.1222
71
16.1217
58
16.1213
58
16.1209
52
16.1205
61
16.12
60
16.1196
75
16.1192
78
16.1188
58
16.1183
72
16.1179
64
16.1175
85
16.117
76
16.1166
63
16.1162
63
16.1158
78
16.1153
61
16.1149
73
16.1145
65
16.1141
100
16.1136
67
16.1132
74
16.1128
66
16.1124
67
16.1119
64
16.1115
73
16.1111
68
16.1107
81
16.1102
71
16.1098
66
16.1094
66
16.1089
81
16.1085
74
16.1081
78
16.1077
69
16.1072
83
16.1068
79
16.1064
80
16.106
72
16.1055
70
16.1051
55
16.1047
68
16.1043
85
16.1038
73
16.1034
68
16.103
83
16.1026
71
16.1021
68
16.1017
71
16.1013
71
16.1009
75
16.1004
69
16.1
69
16.0996
62
16.0992
65
16.0987
65
16.0983
66
16.0979
73
16.0975
68
16.097
71
16.0966
68
16.0962
69
16.0958
63
16.0953
73
16.0949
64
16.0945
85
16.0941
63
16.0936
81
16.0932
77
16.0928
74
16.0924
73
16.0919
75
16.0915
71
16.0911
68
16.0907
80
16.0902
76
16.0898
76
16.0894
73
16.089
68
16.0885
74
16.0881
82
16.0877
82
16.0873
66
16.0868
68
16.0864
65
16.086
64
16.0856
76
16.0851
71
16.0847
89
16.0843
68
16.0839
76
16.0834
82
16.083
66
16.0826
67
16.0822
80
16.0817
59
16.0813
59
16.0809
66
16.0805
66
16.08
65
16.0796
63
16.0792
75
16.0788
80
16.0784
78
16.0779
66
16.0775
59
16.0771
67
16.0767
80
16.0762
69
16.0758
69
16.0754
50
16.075
61
16.0745
79
16.0741
77
16.0737
75
16.0733
74
16.0728
61
16.0724
81
16.072
86
16.0716
74
16.0712
66
16.0707
84
16.0703
66
16.0699
84
16.0695
55
16.069
74
16.0686
68
16.0682
63
16.0678
72
16.0673
73
16.0669
57
16.0665
63
16.0661
77
16.0657
85
16.0652
64
16.0648
80
16.0644
56
16.064
64
16.0635
70
16.0631
70
16.0627
63
16.0623
71
16.0619
68
16.0614
77
16.061
71
16.0606
73
16.0602
73
16.0597
82
16.0593
84
16.0589
78
16.0585
78
16.0581
81
16.0576
75
16.0572
90
16.0568
79
16.0564
64
16.0559
80
16.0555
79
16.0551
67
16.0547
85
16.0543
69
16.0538
84
16.0534
80
16.053
91
16.0526
70
16.0521
77
16.0517
92
16.0513
61
16.0509
81
16.0505
56
16.05
81
16.0496
69
16.0492
83
16.0488
84
16.0484
68
16.0479
75
16.0475
66
16.0471
66
16.0467
65
16.0462
70
16.0458
70
16.0454
52
16.045
61
16.0446
77
16.0441
66
16.0437
67
16.0433
83
16.0429
76
16.0425
80
16.042
end of experiment